<mujoco model="panda nohand">
  <compiler angle="radian" meshdir="assets" autolimits="true"/>

  <actuator>
      <!-- Physical limits of the actuator. -->
      <motor ctrllimited="true" ctrlrange="-80.0 80.0" joint="joint1" name="torq_j1"/>
      <motor ctrllimited="true" ctrlrange="-80.0 80.0" joint="joint2" name="torq_j2"/>
      <motor ctrllimited="true" ctrlrange="-80.0 80.0" joint="joint3" name="torq_j3"/>
      <motor ctrllimited="true" ctrlrange="-80.0 80.0" joint="joint4" name="torq_j4"/>
      <motor ctrllimited="true" ctrlrange="-80.0 80.0" joint="joint5" name="torq_j5"/>
      <motor ctrllimited="true" ctrlrange="-12.0 12.0" joint="joint6" name="torq_j6"/>
      <motor ctrllimited="true" ctrlrange="-12.0 12.0" joint="joint7" name="torq_j7"/>
  </actuator>

  <default>
    <default class="panda">
      <material specular="0.5" shininess="0.25"/>
      <default class="finger">
        <joint axis="0 1 0" type="slide" range="0 0.04"/>
      </default>

      <default class="panda/visual">
        <geom type="mesh" contype="0" conaffinity="0" group="2"/>
      </default>
      <default class="panda/collision">
        <geom type="mesh" contype="0" conaffinity="0" group="3"/>
      </default>
      <site size="0.001" rgba="0.5 0.5 0.5 0.3" group="4"/>
    </default>
  </default>

  <asset>
    <material class="panda" name="white" rgba="1 1 1 1"/>
    <material class="panda" name="off_white" rgba="0.901961 0.921569 0.929412 1"/>
    <material class="panda" name="dark_grey" rgba="0.25 0.25 0.25 1"/>
    <material class="panda" name="green" rgba="0 1 0 1"/>
    <material class="panda" name="light_blue" rgba="0.039216 0.541176 0.780392 1"/>

    <!-- Collision meshes -->
    <mesh name="link0_c" file="link0.stl"/>
    <mesh name="link1_c" file="link1.stl"/>
    <mesh name="link2_c" file="link2.stl"/>
    <mesh name="link3_c" file="link3.stl"/>
    <mesh name="link4_c" file="link4.stl"/>
    <mesh name="link5_c0" file="link5_collision_0.obj"/>
    <mesh name="link5_c1" file="link5_collision_1.obj"/>
    <mesh name="link5_c2" file="link5_collision_2.obj"/>
    <mesh name="link6_c" file="link6.stl"/>
    <mesh name="link7_c" file="link7.stl"/>

    <!-- Visual meshes -->
    <mesh file="link0_0.obj"/>
    <mesh file="link0_1.obj"/>
    <mesh file="link0_2.obj"/>
    <mesh file="link0_3.obj"/>
    <mesh file="link0_4.obj"/>
    <mesh file="link0_5.obj"/>
    <mesh file="link0_7.obj"/>
    <mesh file="link0_8.obj"/>
    <mesh file="link0_9.obj"/>
    <mesh file="link0_10.obj"/>
    <mesh file="link0_11.obj"/>
    <mesh file="link1.obj"/>
    <mesh file="link2.obj"/>
    <mesh file="link3_0.obj"/>
    <mesh file="link3_1.obj"/>
    <mesh file="link3_2.obj"/>
    <mesh file="link3_3.obj"/>
    <mesh file="link4_0.obj"/>
    <mesh file="link4_1.obj"/>
    <mesh file="link4_2.obj"/>
    <mesh file="link4_3.obj"/>
    <mesh file="link5_0.obj"/>
    <mesh file="link5_1.obj"/>
    <mesh file="link5_2.obj"/>
    <mesh file="link6_0.obj"/>
    <mesh file="link6_1.obj"/>
    <mesh file="link6_2.obj"/>
    <mesh file="link6_3.obj"/>
    <mesh file="link6_4.obj"/>
    <mesh file="link6_5.obj"/>
    <mesh file="link6_6.obj"/>
    <mesh file="link6_7.obj"/>
    <mesh file="link6_8.obj"/>
    <mesh file="link6_9.obj"/>
    <mesh file="link6_10.obj"/>
    <mesh file="link6_11.obj"/>
    <mesh file="link6_12.obj"/>
    <mesh file="link6_13.obj"/>
    <mesh file="link6_14.obj"/>
    <mesh file="link6_15.obj"/>
    <mesh file="link6_16.obj"/>
    <mesh file="link7_0.obj"/>
    <mesh file="link7_1.obj"/>
    <mesh file="link7_2.obj"/>
    <mesh file="link7_3.obj"/>
    <mesh file="link7_4.obj"/>
    <mesh file="link7_5.obj"/>
    <mesh file="link7_6.obj"/>
    <mesh file="link7_7.obj"/>
  </asset>

  <worldbody>
    <light name="top" pos="0 0 2" mode="trackcom"/>
    <body name="link0" pos="0 0 0">
      <geom mesh="link0_0" material="off_white"/>
      <geom mesh="link0_1" material="dark_grey"/>
      <geom mesh="link0_2" material="off_white"/>
      <geom mesh="link0_3" material="dark_grey"/>
      <geom mesh="link0_4" material="off_white"/>
      <geom mesh="link0_5" material="dark_grey"/>
      <geom mesh="link0_7" material="white"/>
      <geom mesh="link0_8" material="white"/>
      <geom mesh="link0_9" material="dark_grey"/>
      <geom mesh="link0_10" material="off_white"/>
      <geom mesh="link0_11" material="white"/>
      <geom mesh="link0_c"/>
      <body name="link1" pos="0 0 0.333">
        <inertial pos="0 0 -0.07" mass="3" diaginertia="0.3 0.3 0.3" />
        <joint name="joint1" pos="0 0 0" axis="0 0 1" limited="true" range="-2.8973 2.8973" damping="0.1"/>
        <geom material="white" mesh="link1"/>
        <geom mesh="link1_c"/>
        <body name="link2" pos="0 0 0" quat="0.707107 -0.707107 0 0">
          <inertial pos="0 -0.1 0" mass="3" diaginertia="0.3 0.3 0.3" />
          <joint name="joint2" pos="0 0 0" axis="0 0 1" limited="true" range="-1.7628 1.7628" damping="0.1"/>
          <geom material="white" mesh="link2"/>
          <geom mesh="link2_c"/>
          <body name="link3" pos="0 -0.316 0" quat="0.707107 0.707107 0 0">
            <joint name="joint3" pos="0 0 0" axis="0 0 1" limited="true" range="-2.8973 2.8973" damping="0.1"/>
            <inertial pos="0.04 0 -0.05" mass="2" diaginertia="0.2 0.2 0.2" />
            <geom mesh="link3_0" material="white"/>
            <geom mesh="link3_1" material="white"/>
            <geom mesh="link3_2" material="white"/>
            <geom mesh="link3_3" material="dark_grey"/>
            <geom mesh="link3_c"/>
            <body name="link4" pos="0.0825 0 0" quat="0.707107 0.707107 0 0">
              <inertial pos="-0.04 0.05 0" mass="2" diaginertia="0.2 0.2 0.2" />
              <joint name="joint4" pos="0 0 0" axis="0 0 1" limited="true" range="-3.0718 -0.0698" damping="0.1"/>
              <geom mesh="link4_0" material="white"/>
              <geom mesh="link4_1" material="white"/>
              <geom mesh="link4_2" material="dark_grey"/>
              <geom mesh="link4_3" material="white"/>
              <geom mesh="link4_c"/>
              <body name="link5" pos="-0.0825 0.384 0" quat="0.707107 -0.707107 0 0">
                <inertial pos="0 0 -0.15" mass="2" diaginertia="0.2 0.2 0.2" />
                <joint name="joint5" pos="0 0 0" axis="0 0 1" limited="true" range="-2.8973 2.8973" damping="0.1"/>
                <geom mesh="link5_0" material="dark_grey"/>
                <geom mesh="link5_1" material="white"/>
                <geom mesh="link5_2" material="white"/>
                <geom mesh="link5_c0"/>
                <geom mesh="link5_c1"/>
                <geom mesh="link5_c2"/>
                <body name="link6" pos="0 0 0" quat="0.707107 0.707107 0 0">
                  <inertial pos="0.06 0 0" mass="1.5" diaginertia="0.1 0.1 0.1" />
                  <joint name="joint6" pos="0 0 0" axis="0 0 1" limited="true" range="-0.0175 3.7525" damping="0.01"/>
                  <geom mesh="link6_0" material="off_white"/>
                  <geom mesh="link6_1" material="white"/>
                  <geom mesh="link6_2" material="dark_grey"/>
                  <geom mesh="link6_3" material="white"/>
                  <geom mesh="link6_4" material="white"/>
                  <geom mesh="link6_5" material="white"/>
                  <geom mesh="link6_6" material="white"/>
                  <geom mesh="link6_7" material="light_blue"/>
                  <geom mesh="link6_8" material="light_blue"/>
                  <geom mesh="link6_9" material="dark_grey"/>
                  <geom mesh="link6_10" material="dark_grey"/>
                  <geom mesh="link6_11" material="white"/>
                  <geom mesh="link6_12" material="green"/>
                  <geom mesh="link6_13" material="white"/>
                  <geom mesh="link6_14" material="dark_grey"/>
                  <geom mesh="link6_15" material="dark_grey"/>
                  <geom mesh="link6_16" material="white"/>
                  <geom mesh="link6_c"/>
                  <body name="link7" pos="0.088 0 0" quat="0.707107 0.707107 0 0">
                    <inertial pos="0 0 0.08" mass="0.5" diaginertia="0.05 0.05 0.05" />
                    <joint name="joint7" pos="0 0 0" axis="0 0 1" limited="true" range="-2.8973 2.8973" damping="0.01"/>
                    <geom mesh="link7_0" material="white"/>
                    <geom mesh="link7_1" material="dark_grey"/>
                    <geom mesh="link7_2" material="dark_grey"/>
                    <geom mesh="link7_3" material="dark_grey"/>
                    <geom mesh="link7_4" material="dark_grey"/>
                    <geom mesh="link7_5" material="dark_grey"/>
                    <geom mesh="link7_6" material="dark_grey"/>
                    <geom mesh="link7_7" material="white"/>
                    <geom mesh="link7_c"/>
                  </body>
                </body>
              </body>
            </body>
          </body>
        </body>
      </body>
    </body>
  </worldbody>

  <keyframe>
    <key name="home" qpos="0 0 0 -1.57079 0 1.57079 -0.7853" ctrl="0 0 0 -1.57079 0 1.57079 -0.7853"/>
  </keyframe>
</mujoco>