<mujoco>

  <default>
      <geom contype="0" conaffinity="0" />
  </default>

  <worldbody>
    <body name="link1" pos="0 0 0.0">
      <inertial pos="0 0 0" euler="0 0 0" mass="1.0" diaginertia="0.083958 0.083958 0.00125" />
      <joint axis="1 0 0" name="joint1" pos="0 0 0" type="hinge"/>
      <geom name="clink1" size="0.05 0.5" type="capsule"/>
      <body name="link2" pos="0 0 1.0">
        <inertial pos="0 0 0" euler="0 0 0" mass="1.0" diaginertia="0.083958 0.083958 0.00125" />
        <joint axis="1 0 0" name="joint2" pos="0 0 0" type="hinge"/>
        <geom name="clink2"  size="0.05 0.5" type="capsule"/>
      </body>
    </body>

  </worldbody>

  <actuator>
    <motor gear="1" joint="joint1" name="torque1"/>
    <motor gear="1" joint="joint2" name="torque2"/>
  </actuator>

</mujoco>
